Workbook

Sheet INVOICE
A1: COMMERCIAL INVOICE
A2: Shipper/Exporter | E2: No. & Date of Invoice
A3: 登壹企業股份有限公司 | E3: TW-17546
A4: 中國台灣新北市中和區中山路三段110號9樓 | E4: 45883
A7: Bill To: | E7: Payment Term
A8: 中磊電子（蘇州）有限公司
A9: 蘇州工業園區唐莊路8號
A10: 电话：0512-67613993 传真：0512-67624500
A12: Ship To: | E12: Trade Term
A13: 中磊電子（蘇州）有限公司 | E13: DDU-SZ
A14: 蘇州工業園區唐莊路8號
A15: 电话：0512-67613993 传真：0512-67624500
A17: Port of Loading | C17: Port of Discharge | E17: Remarks:
A20: Carrier | C20: Sailing on/or About
E21: 贸易国： | F21: Taiwan, China
A22: ITEM | B22: Part No. | C22: PO No. | D22: Description of Goods | E22: Quantity | F22: Unit | G22: Unit Price | H22: Currency | I22: Amount | J22: COO | K22: COD | L22: 品牌 | M22: 品牌类型 | N22: 型号 | O22: Net WT(KGS)
A23: 1 | B23: 3604754AMS | C23: 2250500261 | D23: UT6045N-4R7M | E23: 67000 | F23: PCS | G23: 0.016 | H23: USD | I23: =ROUND(E23*G23,2) -> 1072 | J23: china | L23: 登壹牌 | M23: 境內自主品牌 | N23: 305-70504
A24: 2 | B24: 3600000KMS | C24: 2250503742 | D24: UT6045N-1R0M | E24: 12000 | F24: PCS | G24: 0.016 | H24: USD | I24: =ROUND(E24*G24,2) -> 192 | J24: china | L24: 登壹牌 | M24: 境內自主品牌 | N24: 305-70511
A25: 3 | B25: 36033537MS | C25: 2250501410 | D25: UT6045N-3R3M | E25: 8000 | F25: PCS | G25: 0.016 | H25: USD | I25: =ROUND(E25*G25,2) -> 128 | J25: china | L25: 登壹牌 | M25: 境內自主品牌 | N25: 305-70503
A26: 4 | B26: 3603352QMS | C26: 2250603281 | D26: CD43N-3R3M | E26: 6000 | F26: PCS | G26: 0.0118 | H26: USD | I26: =ROUND(E26*G26,2) -> 70.8 | J26: china | L26: 登壹牌 | M26: 境內自主品牌 | N26: 306-56203
A27: 5 | B27: 3670000BMS | C27: 2250502425 | D27: TM100605N-302 | E27: 1976 | F27: PCS | G27: 0.125 | H27: USD | I27: =ROUND(E27*G27,2) -> 247 | J27: china | L27: 登壹牌 | M27: 境內自主品牌 | N27: 302-98111
A28: 6 | B28: 3670000BMS | C28: 2250701486 | D28: TM100605N-302 | E28: 4936 | F28: PCS | G28: 0.125 | H28: USD | I28: =ROUND(E28*G28,2) -> 617 | J28: china | L28: 登壹牌 | M28: 境內自主品牌 | N28: 302-98111
A29: 7 | B29: 3670004MMS | C29: 2250300434 | D29: TM100605N-302-P | E29: 286 | F29: PCS | G29: 0.189 | H29: USD | I29: =ROUND(E29*G29,2) -> 54.05 | J29: china | L29: 登壹牌 | M29: 境內自主品牌 | N29: 302-98555
A30: 8 | B30: 3670004MMS | C30: 2250500218 | D30: TM100605N-302-P | E30: 3432 | F30: PCS | G30: 0.189 | H30: USD | I30: =ROUND(E30*G30,2) -> 648.65 | J30: china | L30: 登壹牌 | M30: 境內自主品牌 | N30: 302-98555
A31: 9 | B31: 3670004MMS | C31: 2250602366 | D31: TM100605N-302-P | E31: 4576 | F31: PCS | G31: 0.189 | H31: USD | I31: =ROUND(E31*G31,2) -> 864.86 | J31: china | L31: 登壹牌 | M31: 境內自主品牌 | N31: 302-98555
A32: 10 | B32: 3670004MMS | C32: 2250700674 | D32: TM100605N-302-P | E32: 7150 | F32: PCS | G32: 0.189 | H32: USD | I32: =ROUND(E32*G32,2) -> 1351.35 | J32: china | L32: 登壹牌 | M32: 境內自主品牌 | N32: 302-98555
C34: TOTAL | E34: =SUM(E23:E33) -> 115356 | I34: =SUM(I23:I33) -> 5245.71 | O34: =SUM(O23:O33) -> 0
A36: 1、進境口岸關別代碼 | G36: 5726中山物流
A37: 2、申報地口岸關別代碼 | G37: 5726中山物流
A38: 3、報關行名稱及代碼 | G38: 中山市科達報關服務有限公司 | K38: 4420980168
A39: 4、關聯手冊（賬冊）編號 | G39: L5726B25A014
A40: 5、貿易國 | G40: 中國台灣
A41: 6、原產國 | G41: 中國
A42: 7、包裝種類 | G42: 99
A43: 8、成交方式 | G43: DDU
A44: 9、申報計量單位 | G44: 个

Sheet PACKING
A1: PACKING LIST
A2: Shipper/Exporter | G2: No & Date of Invoice
A3: 登壹企業股份有限公司 | G3: TW-17546
A4: 中國台灣新北市中和區中山路三段110號9樓 | G4: 45883
A5: Bill To: | G5: Remarks:
A6: 中磊電子(蘇州)有限公司
A7: 中國江蘇省蘇州工業園區唐庄路8號 尚飛 #7528 Tel:512-67613993 Fax:512-66699177
A9: Ship To:
A10: 中磊電子(蘇州)有限公司
A11: 中國江蘇省蘇州工業園區唐庄路8號 尚飛 #7528 Tel:512-67613993 Fax:512-66699177
A14: Port of Departure | E14: Port of Arrival
A16: Carrier | E16: Sailing on/or About
A17: CTNS | B17: Package | C17: PO No. | D17: Part No. | E17: Description of Goods | G17: Quantity | H17: Unit | I17: Number of pieces | J17: Net WT | K17: Gross WT | L17: MEASUREMENT L*W*H(CM)
J18: KGS | K18: KGS
A19: 1-11 | B19: 6000 | C19: 2250500261 | D19: 3604754AMS | E19: UT6045N-4R7M | G19: 66000 | H19: PCS | I19: =G19/B19 -> 11 | J19: =ROUND(0.59*G19/1000,2) -> 38.94 | K19: =ROUND(6.5*I19,2) -> 71.5 | L19: 36*36*19
A20: 12 | B20: 1000 | C20: 2250500261 | D20: 3604754AMS | E20: UT6045N-4R7M | G20: 1000 | H20: PCS | I20: =G20/B20 -> 1 | J20: =ROUND(0.59*G20/1000,2) -> 0.59 | K20: =ROUND(1.5*I20,2) -> 1.5 | L20: 36*36*9.5
A21: 13-14 | B21: 6000 | C21: 2250503742 | D21: 3600000KMS | E21: UT6045N-1R0M | G21: 12000 | H21: PCS | I21: =G21/B21 -> 2 | J21: =ROUND(0.62*G21/1000,2) -> 7.44 | K21: =ROUND(6.3*I21,2) -> 12.6 | L21: 36*36*19
A22: 15 | B22: 6000 | C22: 2250501410 | D22: 36033537MS | E22: UT6045N-3R3M | G22: 6000 | H22: PCS | I22: =G22/B22 -> 1 | J22: =ROUND(0.703*G22/1000,2) -> 4.22 | K22: =ROUND(6.5*I22,2) -> 6.5 | L22: 36*36*19
A23: 16 | B23: 2000 | C23: 2250501410 | D23: 36033537MS | E23: UT6045N-3R3M | G23: 2000 | H23: PCS | I23: =G23/B23 -> 1 | J23: =ROUND(0.703*G23/1000,2) -> 1.41 | K23: =ROUND(2.5*I23,2) -> 2.5 | L23: 36*36*9.5
A24: 17 | B24: 6000 | C24: 2250603281 | D24: 3603352QMS | E24: CD43N-3R3M | G24: 6000 | H24: PCS | I24: =G24/B24 -> 1 | J24: =ROUND(0.22*G24/1000,2) -> 1.32 | K24: =ROUND(3*I24,2) -> 3 | L24: 36*36*9.5
A25: 18-22 | B25: 1280 | C25: 2250502425 | D25: 3670000BMS | E25: TM100605N-302 | G25: 6400 | H25: PCS | I25: =G25/B25 -> 5 | J25: =ROUND(2.23*G25/1000,2) -> 14.27 | K25: =ROUND(3.5*I25,2) -> 17.5 | L25: 36*36*19
C26: 2250701486 | D26: 3670000BMS | E26: TM100605N-302
A27: 23 | B27: 512 | C27: 2250701486 | D27: 3670000BMS | E27: TM100605N-302 | G27: 512 | H27: PCS | I27: =G27/B27 -> 1 | J27: =ROUND(2.23*G27/1000,2) -> 1.14 | K27: =ROUND(1.7*I27,2) -> 1.7 | L27: 36*36*19
A28: 24-33 | B28: 1430 | C28: 2250300434 | D28: 3670004MMS | E28: TM100605N-302-P | G28: 14300 | H28: PCS | I28: =G28/B28 -> 10 | J28: =ROUND(2.36*G28/1000,2) -> 33.75 | K28: =ROUND(4*I28,2) -> 40 | L28: 36*36*9.5
C29: 2250500218 | D29: 3670004MMS | E29: TM100605N-302-P
C30: 2250602366 | D30: 3670004MMS | E30: TM100605N-302-P
C31: 2250700674 | D31: 3670004MMS | E31: TM100605N-302-P
A32: 34 | B32: 1144 | C32: 2250700674 | D32: 3670004MMS | E32: TM100605N-302-P | G32: 1144 | H32: PCS | I32: =G32/B32 -> 1 | J32: =ROUND(2.36*G32/1000,2) -> 2.7 | K32: =ROUND(3.4*I32,2) -> 3.4
E33: 塑膠棧板X1 | K33: =1*5.5 -> 5.5 | L33: 110*80*15CM
A34: 34 | E34: TOTAL | G34: =SUM(G19:G33) -> 115356 | J34: =SUM(J19:J33) -> 105.78 | K34: =SUM(K19:K33) -> 165.7 | L34: 0.2m³
E35: 件数 | G35: PLT#1(1~34)
E36: 包装种类 | G36: 纸箱/托盘
E37: 托盘材质 | G37: 塑胶托
A39: 1、進境口岸關別代碼 | G39: 5726中山物流
A40: 2、申報地口岸關別代碼 | G40: 5726中山物流
A41: 3、報關行名稱及代碼 | G41: 中山市科達報關服務有限公司 | K41: 4420980168
A42: 4、關聯手冊（賬冊）編號 | G42: L5726B25A014
A43: 5、貿易國 | G43: 中國台灣
A44: 6、原產國 | G44: 中國
A45: 7、包裝種類 | G45: 99
...

Sheet 報關單
A1: 中华人民共和国海关出口货物报关单
B2: 预录入编号 | G2: 海关编号
C3: 关联手（帐）册编号：L5726B25A014
A4: 收发货人 | E4: 出口口岸 | H4: 出口日期 | J4: 申报日期
A5: 登壹电子（开平）有限公司 | E5: 中山物流 | H5: 45884
A6: 生产销售单位 | E6: 运输方式：物流中心 | G6: 运输工具名称 | J6: 提运单号
A7: 登壹电子（开平）有限公司 | E7: 物流中心 | G7: 粤JP9797
A8: 申报单位 | E8: 监管方式 | H8: 征免性质 | J8: 备案号
E9: 一般贸易
A10: 贸易国(地区) | D10: 运抵国(地区) | G10: 指运港 | J10: 境内货源地
A11: 中国 | D11: 中国 | J11: 江门（44079）
A12: 许可证号 | D12: 成交方式 | E12: 运费 | H12: 保费 | J12: 杂费
A14: 合同协议号 | D14: 件数 | E14: 包装种类 | H14: 毛重(千克) | J14: 净重(千克)
A15: TW-17546 | D15: 1 | E15: 托盘 | H15: 165.7 | J15: 105.78
A16: 集装箱号 | D16: 随附单证
A18: 标记唛码及备注：用加固木条
A19: 出口退税 | C19: 登壹牌，MINGSTAR牌 | E19: 用途:抑制电流突变，抑制电磁干扰，非触摸屏
A20: 项号 | B20: 商品编号 | C20: 商品名称、规格型号 | E20: 数量及单位 | G20: 最终目的国(地区) | I20: 单价 | J20: 总价 币制 | L20: 征免
B21: 用途:抑制电流突变
A23: 1 | B23: 85045000 | C23: 电感 | E23: 53.92 | G23: 中国 | I23: =J23/E24 -> 0.015729032 | J23: =發票!G16 -> 1462.8 | K23: 美元
E24: =發票!E16 -> 93000 | F24: 个
B25: 用途：抑制电磁干扰，非触摸屏
A27: 2 | B27: 8548000001 | C27: 滤波器 | E27: 51.86 | G27: 中国 | I27: =J27/E28 -> 0.16921229 | J27: =發票!G17 -> 3782.91 | K27: 美元
E28: =發票!E17 -> 22356 | F28: 个
A31: 录入员 录入单位 | D31: 兹声明以上内容承担如实申报、依法纳税之法律责任 | H31: 海关批注及签章
A34: 报关人员 | D34: 申请单位(签章)

Sheet 銷售合同
A1: 销 售 合 同
A2: PURCHASE CONTRACT
A3: 合同号:TW-17546
A4: CONTRACT NO: | F4: 日期: | G4: 45876
A5: 卖方: | B5: 登壹电子(开平)有限公司 | E5: 买方: | F5: 登壹企业股份有限公司
A6: Buyers: | E6: Sellers:
A7: 地址: | B7: 开平市沙冈工业园兴祥路44-46号 | E7: 地址:
A8: Address: | E8: Address: | F8: 9F., No.110, Sec. 3, Zhongshan Rd., Zhonghe Dist., New Taipei City 23544, Taiwan ,R.O.C.
A9: 电话: | B9: 0750-2226899 | E9: 电话: | F9: 886-2-3234-6785
A10: TEL: | E10: TEL:
A11: 兹经买卖双方同意,由买方购进,卖方出售下列货物,并按下列条款签订本合同:
A12: This CONTRACT is made by and between the Buyers and the Sellers.Whereby it is agred that Buyers and the Sellers
A13: SUPPLY the under mentioned goods according to the terms and condition stipulated below:
A14: 序 号 | B14: 1.商品编号 | C14: 2.品名及规格/客户料号 | E14: 3.数 量 | G14: 4.单 价 | H14: 5.金 额
A15: NO. | B15: H.S | C15: Name of commodity and specifications | E15: Quantity | G15: Unit Price | H15: Amount
A16: 1 | B16: 85045000 | C16: 电感 | E16: =發票!E16 -> 93000 | F16: PCS | G16: =H16/E16 -> 0.015729032 | H16: =發票!G16 -> 1462.8
A17: 2 | B17: 8548000001 | C17: 滤波器 | E17: =發票!E17 -> 22356 | F17: PCS | G17: =H17/E17 -> 0.16921229 | H17: =發票!G17 -> 3782.91
A18: Total Contract Value: | E18: =發票!E18 -> 115356 | G18: Total Value | H18: =發票!G18 -> 5245.71
A19: 允许溢短 %，允许转运.分运。WITH %，morc or ress shipment allowed Both transhipent and parlial shipment apowed.
A20: 6.原产地及制造厂家：Made in china | E20: 7.包装:纸箱
A21: 6.Country Of Origin And Manufacturers: | E21: 7.PACKING:
A22: 8.交货日期: | E22: 9.装运口岸: | F22: KAIPING
A23: 8.Date Of Delivery: | E23: 9.PORT OF SHIPMENT:
A24: 10.目的口岸:江苏 | E24: 11.运输方式: | G24: 物流中心
A25: 10.Port Of Desteination: | E25: 11.Means Of Transportation:
A26: 12.保险: | E26: 13.付款方式: | G26: T/T
A27: 12.Insurance: | E27: 13.Terms Of Payment:
A28: 14.单证:
A29: A.海运:全套清洁已装船海运提单,注明“运费已付”/“运费到付”空白抬头，空白背书面通知买方。
A30: 空运： 份注明“运费已付”/“运费到付”，以买方为收货人的空运单。
A31: 其他方式：一份能证明证明货物已运送给买方，代表货物处置权/所有权的凭证。
A32: B.商业发票一式 份。注明合同号.唛头及信用证号,如系分批装运,须注明分批号。
A33: C.装箱单或重量单一式 份.
A34: D.其它单证:
A35: 14.Documents:
A36: A.In case Of freight:Full set Of clean on board ocean bill of lading made out to order and endorsed in biank
A37: markde“FREIGHT PREPAID”/“FREIGHT TO COLLECT”notily the buyers.
A38: In case of air freight：One copy of air bill consigned to the Buyers，marked“FREIGHT PREPAID”/“FREIGHT COLLECT”.
A39: In other case：One copy of document which can prove the goods has been deilverde to the Buyers，and represents the of contracted goods.
... A43: D.Other documents.
...

Sheet 裝箱明細
A1: 出口货物装箱单
A2: 商 号: | C2: 登壹企业股份有限公司 | G2: 海关编号: | H2: 4407944258
A3: 发货单位: | C3: 登壹电子(开平)有限公司 | G3: 手册编号:
A4: 协议(合同): | C4: TW-17546 | G4: 国内车牌:
A5: 起始国(地区): | G5: 司机姓名﹕
A6: 件数: | B6: 1 | C6: 包裝种类: | D6: 托盘 | E6: 毛重(公斤): | F6: 165.7 | J6: 净重（公斤）：105.78
A7: 品名：电感
A8: 卡板號 PLT# | B8: 箱號 | C8: 型號 | D8: 品名規格 | E8: 數量 (PCS) | F8: 每箱數量（PCS） | G8: 箱數 | H8: 單箱凈重 (KG) | I8: 單箱毛重(KG) | J8: 合計凈重 (KG) | K8: 合計毛重 (KG)
A9: 1 | B9: 1-11 | C9: 305-70504 | D9: UT6045N-4R7M | E9: 66000 | F9: 6000 | G9: 11 | H9: =0.59*F9/1000 -> 3.54 | I9: 6.5 | J9: =ROUND(H9*G9,2) -> 38.94 | K9: =ROUND(G9*I9,2) -> 71.5
B10: 12 | C10: 305-70504 | D10: UT6045N-4R7M | E10: 1000 | F10: 1000 | G10: 1 | H10: =0.59*F10/1000 -> 0.59 | I10: 1.5 | J10: =ROUND(H10*G10,2) -> 0.59 | K10: =ROUND(G10*I10,2) -> 1.5
B11: 13-14 | C11: 305-70511 | D11: UT6045N-1R0M | E11: 12000 | F11: 6000 | G11: 2 | H11: =0.62*F11/1000 -> 3.72 | I11: 6.3 | J11: =ROUND(H11*G11,2) -> 7.44 | K11: =ROUND(G11*I11,2) -> 12.6
B12: 15 | C12: 305-70503 | D12: UT6045N-3R3M | E12: 6000 | F12: 6000 | G12: 1 | H12: =0.703*F12/1000 -> 4.218 | I12: 6.5 | J12: =ROUND(H12*G12,2) -> 4.22 | K12: =ROUND(G12*I12,2) -> 6.5
B13: 16 | C13: 305-70503 | D13: UT6045N-3R3M | E13: 2000 | F13: 2000 | G13: 1 | H13: =0.703*F13/1000 -> 1.406 | I13: 2.5 | J13: =ROUND(H13*G13,2) -> 1.41 | K13: =ROUND(G13*I13,2) -> 2.5
B14: 17 | C14: 306-56203 | D14: CD43N-3R3M | E14: 6000 | F14: 6000 | G14: 1 | H14: =0.22*F14/1000 -> 1.32 | I14: 3 | J14: =ROUND(H14*G14,2) -> 1.32 | K14: =ROUND(G14*I14,2) -> 3
B15: 18-22 | C15: 302-98111 | D15: TM100605N-302 | E15: 1976 | F15: 1280 | G15: 5 | H15: =2.23*E15/1000 -> 4.40648 | I15: 3.5 | J15: =ROUND(H15+H16,2) -> 14.27 | K15: =ROUND(G15*I15,2) -> 17.5
C16: 302-98111 | D16: TM100605N-302 | E16: 4424 | H16: =2.23*E16/1000 -> 9.86552
B17: 23 | C17: 302-98111 | D17: TM100605N-302 | E17: 512 | F17: 512 | G17: 1 | H17: =2.23*E17/1000 -> 1.14176 | I17: 1.7 | J17: =ROUND(H17*G17,2) -> 1.14 | K17: =ROUND(G17*I17,2) -> 1.7
B18: 24-33 | C18: 302-98555 | D18: TM100605N-302-P | E18: 286 | F18: 1430 | G18: 10 | H18: =2.36*E18/1000 -> 0.67496 | I18: 4 | J18: =ROUND(H18+H19+H20+H21,2) -> 33.75 | K18: =ROUND(G18*I18,2) -> 40
C19: 302-98555 | D19: TM100605N-302-P | E19: 3432 | H19: =2.36*E19/1000 -> 8.09952
C20: 302-98555 | D20: TM100605N-302-P | E20: 4576 | H20: =2.36*E20/1000 -> 10.79936
C21: 302-98555 | D21: TM100605N-302-P | E21: 6006 | H21: =2.36*E21/1000 -> 14.17416
B22: 34 | C22: 302-98555 | D22: TM100605N-302-P | E22: 1144 | F22: 1144 | G22: 1 | H22: =2.36*E22/1000 -> 2.69984 | I22: 3.4 | J22: =ROUND(H22*G22,2) -> 2.7 | K22: =ROUND(G22*I22,2) -> 3.4
B23: 塑膠棧板X1 | K23: 5.5
E24: =SUM(E9:E23) -> 115356 | G24: =SUM(G9:G23) -> 34 | H24: =SUM(H9:H23) -> 66.6556 | I24: =SUM(I9:I23) -> 38.9 | J24: =SUM(J9:J23) -> 105.78 | K24: =SUM(K9:K23) -> 165.7

Sheet 發票
A1: 登壹电子(开平)有限公司
A2: MINGSTAR ELECTRNIC(KAIPING)CO.,LTD.
A3: 开平市沙冈工业园兴祥路44-46号
A4: Tel:0750-2226899 Fax:0750-2226788
A5: 发 票
A6: COMMERCIAL INVOICE
F8: 发票号码： | G8: =INVOICE!E3 -> TW-17546
A10: 买方：登壹企业股份有限公司 | E10: 卖方：登壹电子(开平)有限公司
A11: 货源地/产地：广东开平 | E11: 合同号： | F11: =G8 -> TW-17546
A12: 成交方式：FOB 江门 | E12: 付汇方式：电汇
A13: 包装种类：纸箱
A15: 序号 | B15: 商品编码 | C15: Description 品名及规格 | E15: 数量（个） | F15: 单价（USD） | G15: 总价（USD）
A16: 1 | B16: 85045000 | C16: 电感 | E16: =E18-E17 -> 93000 | F16: =G16/E16 -> 0.015729032 | G16: 1462.8
A17: 2 | B17: 8548000001 | C17: 滤波器 | E17: 22356 | F17: =G17/E17 -> 0.16921229 | G17: 3782.91
A18: TOTAL: | E18: =INVOICE!E34 -> 115356 | G18: =SUM(G16:G17) -> 5245.71
D19: 发货单位(签章):登壹电子(开平)有限公司
D20: 45884
