Workbook

Sheet INV
A1: COMMERCIAL INVOICE
A2: Shipper/Exporter: | E2: No. & Date of Invoice:
A3: WENDELL INDUSTRIAL CO.,LTD | E3: QWD910-INV250815004
A4: 新北市新店區寶橋路188號6樓及6樓之1 6F & 6F-1, No.188, Baociao Rd., Sin-Dian District, New Taipei City 231, Taiwan,China | E4: 45884
A6: Bill To: | E6: Payment Term:
A7: Sernet (Suzhou) Technologies Corporation | E7: O/A 120 DAYS
A8: No.8, Tangzhuang Road, Suzhou Industrial Park, Jiangsu,China
A9: Ship To: | E9: Trade Term:
A10: No.8,Tangzhuang Road, Suzhou Industrial Park, Jiangsu, China, 215021 | E10: FOB Taiwan,China
A11: Attn : Eleana Zhang(張平) Tel : 86-512 6761 3993 ext: 6555
A13: Port of Loading | C13: Port of Discharge | E13: Remarks:
A15: Carrier | C15: Sailing on/or About
A16: Morrison Express(Air) | E16: 贸易国： | F16: Taiwan,China
A17: ITEM | B17: Part No. | C17: PO No. | D17: Description of Goods | E17: Quantity | F17: Unit | G17: Unit Price | H17: Currency | I17: Amount | J17: COO | K17: COD | L17: 品牌 | M17: 品牌类型 | N17: 型号 | O17: Net WT(KGS)
A18: 1 | B18: 30133310NK | C18: 2250303695 | D18: Diode | E18: 200000 | F18: PCS | G18: 0.0145 | H18: USD | I18: =ROUND(E18*G18,2) -> 2900 | J18: China | L18: Nichtek | M18: 境外品牌(其他) | N18: D1215-3R3 | O18: 1.6
A19: 2 | B19: 30194110NK | C19: 2250500410 | D19: Diode | E19: 3000 | F19: PCS | G19: 0.0618 | H19: USD | I19: =ROUND(E19*G19,2) -> 185.4 | J19: China | L19: Nichtek | M19: 境外品牌(其他) | N19: D9411-580F | O19: 1.3
A20: 3 | B20: 30194110NK | C20: 2250500829 | D20: Diode | E20: 3000 | F20: PCS | G20: 0.0618 | H20: USD | I20: =ROUND(E20*G20,2) -> 185.4 | J20: China | L20: Nichtek | M20: 境外品牌(其他) | N20: D9411-580F | O20: "
A21: 4 | B21: 301ES1D0NK | C21: 2241200664 | D21: Diode | E21: 5000 | F21: PCS | G21: 0.0054 | H21: USD | I21: =ROUND(E21*G21,2) -> 27 | J21: China | L21: Nichtek | M21: 境外品牌(其他) | N21: R6E14-201A | O21: 0.6
A22: 5 | B22: 30261140NK | C22: 2250303695 | D22: Diode | E22: 9000 | F22: PCS | G22: 0.0058 | H22: USD | I22: =ROUND(E22*G22,2) -> 52.2 | J22: China | L22: Nichtek | M22: 境外品牌(其他) | N22: Z6114-430B | O22: 0.3
A23: 6 | B23: 30442150NK | C23: 2250800633 | D23: ESD SUPPRESSOR | E23: 5000 | F23: PCS | G23: 0.0073 | H23: USD | I23: =ROUND(E23*G23,2) -> 36.5 | J23: China | L23: Nichtek | M23: 境外品牌(其他) | N23: E4215-5R0 | O23: 0.1
A24: 7 | B24: 32199210NK | C24: 2250402796 | D24: Transistor | E24: 3000 | F24: PCS | G24: 0.0022 | H24: USD | I24: =ROUND(E24*G24,2) -> 6.6 | J24: China | L24: Nichtek | M24: 境外品牌(其他) | N24: GT9921-600N | O24: 3.6
A25: 8 | B25: 32199210NK | C25: 2250402796 | D25: Transistor | E25: 9000 | F25: PCS | G25: 0.0022 | H25: USD | I25: =ROUND(E25*G25,2) -> 19.8 | J25: China | L25: Nichtek | M25: 境外品牌(其他) | N25: GT9921-600N | O25: "
A26: 9 | B26: 32199210NK | C26: 2250402796 | D26: Transistor | E26: 6000 | F26: PCS | G26: 0.0022 | H26: USD | I26: =ROUND(E26*G26,2) -> 13.2 | J26: China | L26: Nichtek | M26: 境外品牌(其他) | N26: GT9921-600N | O26: "
A27: 10 | B27: 32199210NK | C27: 2250402796 | D27: Transistor | E27: 6000 | F27: PCS | G27: 0.0022 | H27: USD | I27: =ROUND(E27*G27,2) -> 13.2 | J27: China | L27: Nichtek | M27: 境外品牌(其他) | N27: GT9921-600N | O27: "
A28: 11 | B28: 32199210NK | C28: 2250403043 | D28: Transistor | E28: 9000 | F28: PCS | G28: 0.0022 | H28: USD | I28: =ROUND(E28*G28,2) -> 19.8 | J28: China | L28: Nichtek | M28: 境外品牌(其他) | N28: GT9921-600N | O28: "
A29: 12 | B29: 32199210NK | C29: 2250403043 | D29: Transistor | E29: 6000 | F29: PCS | G29: 0.0022 | H29: USD | I29: =ROUND(E29*G29,2) -> 13.2 | J29: China | L29: Nichtek | M29: 境外品牌(其他) | N29: GT9921-600N | O29: "
A30: 13 | B30: 32199210NK | C30: 2250403043 | D30: Transistor | E30: 6000 | F30: PCS | G30: 0.0022 | H30: USD | I30: =ROUND(E30*G30,2) -> 13.2 | J30: China | L30: Nichtek | M30: 境外品牌(其他) | N30: GT9921-600N | O30: "
A31: 14 | B31: 32199210NK | C31: 2250403298 | D31: Transistor | E31: 9000 | F31: PCS | G31: 0.0022 | H31: USD | I31: =ROUND(E31*G31,2) -> 19.8 | J31: China | L31: Nichtek | M31: 境外品牌(其他) | N31: GT9921-600N | O31: "
A32: 15 | B32: 32199210NK | C32: 2250403298 | D32: Transistor | E32: 6000 | F32: PCS | G32: 0.0022 | H32: USD | I32: =ROUND(E32*G32,2) -> 13.2 | J32: China | L32: Nichtek | M32: 境外品牌(其他) | N32: GT9921-600N | O32: "
A33: 16 | B33: 32199210NK | C33: 2250403298 | D33: Transistor | E33: 6000 | F33: PCS | G33: 0.0022 | H33: USD | I33: =ROUND(E33*G33,2) -> 13.2 | J33: China | L33: Nichtek | M33: 境外品牌(其他) | N33: GT9921-600N | O33: "
A34: 17 | B34: 32199210NK | C34: 2250500410 | D34: Transistor | E34: 9000 | F34: PCS | G34: 0.0022 | H34: USD | I34: =ROUND(E34*G34,2) -> 19.8 | J34: China | L34: Nichtek | M34: 境外品牌(其他) | N34: GT9921-600N | O34: "
A35: 18 | B35: 32199210NK | C35: 2250500410 | D35: Transistor | E35: 6000 | F35: PCS | G35: 0.0022 | H35: USD | I35: =ROUND(E35*G35,2) -> 13.2 | J35: China | L35: Nichtek | M35: 境外品牌(其他) | N35: GT9921-600N | O35: "
A36: 19 | B36: 32199210NK | C36: 2250500410 | D36: Transistor | E36: 6000 | F36: PCS | G36: 0.0022 | H36: USD | I36: =ROUND(E36*G36,2) -> 13.2 | J36: China | L36: Nichtek | M36: 境外品牌(其他) | N36: GT9921-600N | O36: "
... A40: 23 | B40: 32199210NK | C40: 2250500829 | D40: Transistor | E40: 3000 | F40: PCS | G40: 0.0022 | H40: USD | I40: =ROUND(E40*G40,2) -> 6.6 | J40: China | L40: Nichtek | M40: 境外品牌(其他) | N40: GT9921-600N | O40: "
A41: 24 | B41: 32299210NK | C41: 2250303746 | D41: Transistor | E41: 9000 | F41: PCS | G41: 0.0022 | H41: USD | I41: =ROUND(E41*G41,2) -> 19.8 | J41: China | L41: Nichtek | M41: 境外品牌(其他) | N41: GT9921-400P | O41: 0.5
A42: 25 | B42: 32299210NK | C42: 2250402796 | D42: Transistor | E42: 6000 | F42: PCS | G42: 0.0022 | H42: USD | I42: =ROUND(E42*G42,2) -> 13.2 | J42: China | L42: Nichtek | M42: 境外品牌(其他) | N42: GT9921-400P | O42: "
C44: TOTAL | E44: =SUM(E18:E42) -> 351000 | I44: =SUM(I18:I42) -> 3663.7 | O44: =SUM(O18:O42) -> 8
M45: WENDELL INDUSTRIAL CO.,LTD
M48: AUTHORIZED SIGNATURE

Sheet PAK
A1: PACKING LIST
A3: Shipper/Exporter: | F3: No & Date of Invoice:
A4: WENDELL INDUSTRIAL CO.,LTD | F4: =INV!E3 -> QWD910-INV250815004
A5: 新北市新店區寶橋路188號6樓及6樓之1 6F & 6F-1, No.188, Baociao Rd., Sin-Dian District, New Taipei City 231, Taiwan,China | F5: =INV!E4 -> 45884
A7: Bill To: | F7: Remarks:
A8: Sernet (Suzhou) Technologies Corporation
A9: No.8, Tangzhuang Road, Suzhou Industrial Park, Jiangsu,China
A11: Ship To:
A12: No.8,Tangzhuang Road, Suzhou Industrial Park, Jiangsu, China, 215021
A13: Attn : Eleana Zhang(張平) Tel : 86-512 6761 3993 ext: 6555
A15: Port of Departure | D15: Port of Arrival
A17: Carrier | D17: Sailing on/or About
A18: Morrison Express(Air)
A19: CTNS | B19: PO No. | C19: Part No. | D19: Description of Goods | F19: Quantity | G19: Unit | H19: Net WT | I19: Gross WT | J19: MEASUREMENT L*W*H(CM)
H20: KGS | I20: KGS
A21: 1 | B21: 2250303695 | C21: 30133310NK | D21: Nichtek-D1215-3R3 | E21: Diode | F21: 200000 | G21: PCS | H21: 1.6 | I21: 2.1 | J21: 38*20*21
A22: 2 | B22: 2250500410 | C22: 30194110NK | D22: Nichtek-D9411-580F | E22: Diode | F22: 3000 | G22: PCS | H22: 1.3 | I22: 2.5 | J22: 37*37*18
A23: " | B23: 2250500829 | C23: 30194110NK | D23: Nichtek-D9411-580F | E23: Diode | F23: 3000 | G23: PCS | H23: " | I23: " | J23: "
A24: 3 | B24: 2241200664 | C24: 301ES1D0NK | D24: Nichtek-R6E14-201A | E24: Diode | F24: 5000 | G24: PCS | H24: 0.6 | I24: 1.7 | J24: 37*37*18
A25: 4 | B25: 2250303695 | C25: 30261140NK | D25: Nichtek-Z6114-430B | E25: Diode | F25: 9000 | G25: PCS | H25: 0.3 | I25: 0.4 | J25: 19*9*20
A26: 5 | B26: 2250800633 | C26: 30442150NK | D26: Nichtek-E4215-5R0 | E26: ESD SUPPRESSOR | F26: 5000 | G26: PCS | H26: 0.1 | I26: 0.2 | J26: 19*9*20
A27: 6 | B27: 2250402796 | C27: 32199210NK | D27: Nichtek-GT9921-600N | E27: Transistor | F27: 3000 | G27: PCS | H27: 3.6 | I27: 4.3 | J27: 38*29*22
A28: " | B28: 2250402796 | C28: 32199210NK | D28: Nichtek-GT9921-600N | E28: Transistor | F28: 9000 | G28: PCS | H28: " | I28: " | J28: "
A29: " | B29: 2250402796 | C29: 32199210NK | D29: Nichtek-GT9921-600N | E29: Transistor | F29: 6000 | G29: PCS | H29: " | I29: " | J29: "
A30: " | B30: 2250402796 | C30: 32199210NK | D30: Nichtek-GT9921-600N | E30: Transistor | F30: 6000 | G30: PCS | H30: " | I30: " | J30: "
A31: " | B31: 2250403043 | C31: 32199210NK | D31: Nichtek-GT9921-600N | E31: Transistor | F31: 9000 | G31: PCS | H31: " | I31: " | J31: "
A32: " | B32: 2250403043 | C32: 32199210NK | D32: Nichtek-GT9921-600N | E32: Transistor | F32: 6000 | G32: PCS | H32: " | I32: " | J32: "
A33: " | B33: 2250403043 | C33: 32199210NK | D33: Nichtek-GT9921-600N | E33: Transistor | F33: 6000 | G33: PCS | H33: " | I33: " | J33: "
A34: " | B34: 2250403298 | C34: 32199210NK | D34: Nichtek-GT9921-600N | E34: Transistor | F34: 9000 | G34: PCS | H34: " | I34: " | J34: "
A35: " | B35: 2250403298 | C35: 32199210NK | D35: Nichtek-GT9921-600N | E35: Transistor | F35: 6000 | G35: PCS | H35: " | I35: " | J35: "
A36: " | B36: 2250403298 | C36: 32199210NK | D36: Nichtek-GT9921-600N | E36: Transistor | F36: 6000 | G36: PCS | H36: " | I36: " | J36: "
A37: " | B37: 2250500410 | C37: 32199210NK | D37: Nichtek-GT9921-600N | E37: Transistor | F37: 9000 | G37: PCS | H37: " | I37: " | J37: "
A38: " | B38: 2250500410 | C38: 32199210NK | D38: Nichtek-GT9921-600N | E38: Transistor | F38: 6000 | G38: PCS | H38: " | I38: " | J38: "
A39: " | B39: 2250500410 | C39: 32199210NK | D39: Nichtek-GT9921-600N | E39: Transistor | F39: 6000 | G39: PCS | H39: " | I39: " | J39: "
... A43: " | B43: 2250500829 | C43: 32199210NK | D43: Nichtek-GT9921-600N | E43: Transistor | F43: 3000 | G43: PCS | H43: " | I43: " | J43: "
A44: 7 | B44: 2250303746 | C44: 32299210NK | D44: Nichtek-GT9921-400P | E44: Transistor | F44: 9000 | G44: PCS | H44: 0.5 | I44: 0.6 | J44: 19*9*20
A45: " | B45: 2250402796 | C45: 32299210NK | D45: Nichtek-GT9921-400P | E45: Transistor | F45: 6000 | G45: PCS | H45: " | I45: " | J45: "
A47: 7 | E47: TOTAL | F47: =SUM(F21:F46) -> 351000 | H47: =SUM(H21:H46) -> 8 | I47: =SUM(I21:I46) -> 11.8 | J47: 0.10m³
E48: 件数 | F48: 7
E49: 包装种类 | F49: 纸箱
...

Sheet 合同
A1: 产品购销合同
A2: 供 方：穩得實業股份有限公司
A3: 需 方：中怡數寬科技有限公司
A4: 合同号: | B4: =INV!E3 -> QWD910-INV250815004
A5: 一、产品名称、型号、数量及金额
A7: 合同号 | B7: 品名及料号 | D7: 单位 | E7: 数量 | F7: 单价 | G7: 金额 | H7: 币制
A8: =INV!E3 -> QWD910-INV250815004 | B8: Nichtek-D1215-3R3 | D8: PCS | E8: 200000 | F8: 0.0145 | G8: =F8*E8 -> 2900 | H8: USD
A9: =INV!E3 -> QWD910-INV250815004 | B9: Nichtek-D9411-580F | D9: PCS | E9: 6000 | F9: 0.0618 | G9: =F9*E9 -> 370.8 | H9: USD
A10: =INV!E3 -> QWD910-INV250815004 | B10: Nichtek-R6E14-201A | D10: PCS | E10: 5000 | F10: 0.0054 | G10: =F10*E10 -> 27 | H10: USD
A11: =INV!E3 -> QWD910-INV250815004 | B11: Nichtek-Z6114-430B | D11: PCS | E11: 9000 | F11: 0.0058 | G11: =F11*E11 -> 52.2 | H11: USD
A12: =INV!E3 -> QWD910-INV250815004 | B12: Nichtek-E4215-5R0 | D12: PCS | E12: 5000 | F12: 0.0073 | G12: =F12*E12 -> 36.5 | H12: USD
A13: =INV!E3 -> QWD910-INV250815004 | B13: Nichtek-GT9921-600N | D13: PCS | E13: 111000 | F13: 0.0022 | G13: =F13*E13 -> 244.2 | H13: USD
A14: =INV!E3 -> QWD910-INV250815004 | B14: Nichtek-GT9921-400P | D14: PCS | E14: 15000 | F14: 0.0022 | G14: =F14*E14 -> 33 | H14: USD
E16: =SUM(E8:E14) -> 351000 | G16: =SUM(G8:G14) -> 3663.7
A18: 二、交(提)货地点、方式：中怡数宽科技（苏州）有限公司
A19: 三、运输方式及到达站港口和费用负担： FOB 供方承担运费
A20: 四、包装标准、包装物的供应与回收和费用负担：供方
A21: 五、验收标准、方法及提出议期限：1个月
A22: 六、交货日期： | B22: =INV!E4 -> 45884
A23: 七、结算方式：月結 120天
A25: 供方： | F25: 需方：
A26: 单位名称： | B26: 穩得實業股份有限公司 | C26: 单位名称：中怡（苏州）科技有限公司 | F26: 单位名称：中怡数宽科技（苏州）有限公司
A27: 单位地址： | B27: 新北市新店區寶橋路188號6樓及6樓之一 | C27: 单位地址：蘇州工業園區唐莊路8號 | F27: 单位地址：蘇州工業園區唐莊路8號
A28: 电话： | B28: 02 2917-5770 | C28: 蘇州市高新區大同路8號
A29: 传真： | B29: 02 2917-3752
